Workbook

Sheet koronahun
A1: Dátum | B1: Regisztrált esetek száma | C1: Új esetek száma | D1: Elhunytak | E1: Gyógyultak | F1: Mintavétel száma | G1: Egymillió lakosra elvégzett tesztek száma | H1: Kórházi karanténba zártak száma | I1: Regisztrált esetek százalékos változása az előző naphoz viszonyítva | J1: Pozitív tesztek aránya | K1: A mintavételek számának százalékos változása az előző naphoz képest | L1: Aktív fertőzöttek száma | M1: Elhunytak aránya Magyarországon | N1: Gyógyultak aránya Magyarországon | O1: Hatósági házi karantén | P1: Új mintavételek száma | Q1: Új esetek aránya az új mintavételekhez képest | R1: Az új elhunytak száma naponta | S1: Új gyógyultak naponta | T1: Kórházi ápoltak száma | U1: Lélegeztetőgépen lévők száma | V1: Aktív esetek/összes eset | W1: Kórházi ápoltak számának változása az előző naphoz képest | X1: Lélegeztetőgépen lévők számának változása az előző naphoz képest | Y1: Kórházi ápoltak aránya az aktív eseteken belül | Z1: Lélegeztetőgépen lévők aránya a kórházi ápoltakon belül | AA1: Növekedési faktor | AB1: Hétnapos mozgóátlag | AC1: Hétnapos csúszóátlag | AD1: Hétnapos csúszóátlag | AE1: Hétnapos csúszóátlag | AF1: Hétnapos csúszóátlag | AG1: Beoltottak száma Magyarországon | AH1: Új beoltottak száma Magyarországon | AI1: Hétnapos csúszóátlag | AJ1: Második oltás | AK1: Második oltás napi | AL1: Hétnapos csúszóátlag | AM1: Hétnapos csúszóátlag
A2: 43894 | B2: 2 | C2: 2 | F2: 230 | H2: 21 | J2: 0.0087 | L2: 2 | V2: =L2/B2 -> 1
A3: 43895 | B3: 4 | C3: 2 | F3: 230 | H3: 40 | J3: 0.0174 | L3: 4 | P3: 0 | V3: =L3/B3 -> 1 | W3: =T3-T2 -> 0 | X3: =U3-U2 -> 0
A4: 43896 | B4: 4 | C4: 0 | F4: 269 | G4: =F4/9.8 -> 27.44898 | H4: 39 | J4: 0.0149 | K4: 0.17 | L4: 4 | P4: 39 | V4: =L4/B4 -> 1 | W4: =T4-T3 -> 0 | X4: =U4-U3 -> 0
A5: 43897 | B5: 5 | C5: 1 | F5: 319 | G5: =F5/9.8 -> 32.55102 | H5: 48 | I5: 0.25 | J5: 0.0157 | K5: 0.186 | L5: 5 | P5: 50 | Q5: 0.02 | V5: =L5/B5 -> 1 | W5: =T5-T4 -> 0 | X5: =U5-U4 -> 0
A6: 43898 | B6: 7 | C6: 2 | F6: 362 | G6: =F6/9.8 -> 36.938776 | H6: 67 | I6: 0.4 | J6: 0.0193 | K6: 0.135 | L6: 7 | P6: 43 | Q6: 0.0465 | V6: =L6/B6 -> 1 | W6: =T6-T5 -> 0 | X6: =U6-U5 -> 0
A7: 43899 | B7: 9 | C7: 2 | F7: 362 | G7: =F7/9.8 -> 36.938776 | H7: 67 | I7: 0.2857 | J7: 0.0249 | L7: 9 | P7: 0 | V7: =L7/B7 -> 1 | W7: =T7-T6 -> 0 | X7: =U7-U6 -> 0
A8: 43900 | B8: 12 | C8: 3 | F8: 531 | G8: =F8/9.8 -> 54.183673 | H8: 53 | I8: 0.3333 | J8: 0.0226 | K8: 0.467 | L8: 12 | P8: 169 | Q8: 0.0178 | V8: =L8/B8 -> 1 | W8: =T8-T7 -> 0 | X8: =U8-U7 -> 0 | AC8: =SUM(C2:C8)/7 -> 1.7142857 | AE8: =SUM(P2:P8)/7 -> 43
A9: 43901 | B9: 13 | C9: 1 | F9: 609 | G9: =F9/9.8 -> 62.142857 | H9: 69 | I9: 0.0833 | J9: 0.0213 | K9: 0.147 | L9: 13 | P9: 78 | Q9: 0.0128 | V9: =L9/B9 -> 1 | W9: =T9-T8 -> 0 | X9: =U9-U8 -> 0 | AC9: =SUM(C3:C9)/7 -> 1.5714286 | AE9: =SUM(P3:P9)/7 -> 54.142857
A10: 43902 | B10: 16 | C10: 3 | F10: 730 | G10: =F10/9.8 -> 74.489796 | H10: 65 | I10: 0.2308 | J10: 0.0219 | K10: 0.199 | L10: 16 | P10: 121 | Q10: 0.0248 | V10: =L10/B10 -> 1 | W10: =T10-T9 -> 0 | X10: =U10-U9 -> 0 | AC10: =SUM(C4:C10)/7 -> 1.7142857 | AE10: =SUM(P4:P10)/7 -> 71.428571
A11: 43903 | B11: 19 | C11: 3 | E11: 1 | F11: 858 | G11: =F11/9.8 -> 87.55102 | H11: 79 | I11: 0.1875 | J11: 0.0221 | K11: 0.175 | L11: 18 | N11: 0.0526 | P11: 128 | Q11: 0.0234 | S11: 1 | V11: =L11/B11 -> 0.94736842 | W11: =T11-T10 -> 0 | X11: =U11-U10 -> 0 | AC11: =SUM(C5:C11)/7 -> 2.1428571 | AE11: =SUM(P5:P11)/7 -> 84.142857 | AF11: =SUM(Q5:Q11)/7 -> 0.020757143
A12: 43904 | B12: 30 | C12: 11 | E12: 1 | F12: 1014 | G12: =F12/9.8 -> 103.46939 | H12: 79 | I12: 0.5789 | J12: 0.0296 | K12: 0.182 | L12: 29 | N12: 0.0333 | P12: 156 | Q12: 0.0705 | S12: 0 | V12: =L12/B12 -> 0.96666667 | W12: =T12-T11 -> 0 | X12: =U12-U11 -> 0 | AC12: =SUM(C6:C12)/7 -> 3.5714286 | AE12: =SUM(P6:P12)/7 -> 99.285714 | AF12: =SUM(Q6:Q12)/7 -> 0.027971429
A13: 43905 | B13: 32 | C13: 2 | E13: 1 | F13: 1236 | G13: =F13/9.8 -> 126.12245 | H13: 159 | I13: 0.0667 | J13: 0.0259 | K13: 0.219 | L13: 31 | N13: 0.0313 | P13: 222 | Q13: 0.009 | S13: 0 | V13: =L13/B13 -> 0.96875 | W13: =T13-T12 -> 0 | X13: =U13-U12 -> 0 | AC13: =SUM(C7:C13)/7 -> 3.5714286 | AE13: =SUM(P7:P13)/7 -> 124.85714 | AF13: =SUM(Q7:Q13)/7 -> 0.022614286
A14: 43906 | B14: 39 | C14: 7 | D14: 1 | E14: 2 | F14: 1470 | G14: =F14/9.8 -> 150 | H14: 137 | I14: 0.2188 | J14: 0.0265 | K14: 0.189 | L14: 36 | M14: 0.0256 | N14: 0.0513 | P14: 234 | Q14: 0.0299 | R14: 1 | S14: 1 | V14: =L14/B14 -> 0.92307692 | W14: =T14-T13 -> 0 | X14: =U14-U13 -> 0 | AC14: =SUM(C8:C14)/7 -> 4.2857143 | AE14: =SUM(P8:P14)/7 -> 158.28571 | AF14: =SUM(Q8:Q14)/7 -> 0.026885714
A15: 43907 | B15: 50 | C15: 11 | D15: 1 | E15: 2 | F15: 1587 | G15: =F15/9.8 -> 161.93878 | H15: 137 | I15: 0.2821 | J15: 0.0315 | K15: 0.08 | L15: 47 | M15: 0.02 | N15: 0.04 | P15: 117 | Q15: 0.094 | R15: 0 | S15: 0 | V15: =L15/B15 -> 0.94 | W15: =T15-T14 -> 0 | X15: =U15-U14 -> 0 | AA15: =(C9+C10+C11+C12+C13+C14+C15)/(C2+C3+C4+C5+C6+C7+C8) -> 3.1666667 | AC15: =SUM(C9:C15)/7 -> 5.4285714 | AE15: =SUM(P9:P15)/7 -> 150.85714 | AF15: =SUM(Q9:Q15)/7 -> 0.037771429
A16: 43908 | B16: 58 | C16: 8 | D16: 1 | E16: 2 | F16: 1803 | G16: =F16/9.8 -> 183.97959 | H16: 122 | I16: 0.16 | J16: 0.0322 | K16: 0.136 | L16: 55 | M16: 0.0172 | N16: 0.0345 | O16: 2817 | P16: 216 | Q16: 0.037 | R16: 0 | S16: 0 | V16: =L16/B16 -> 0.94827586 | W16: =T16-T15 -> 0 | X16: =U16-U15 -> 0 | AA16: =(C10+C11+C12+C13+C14+C15+C16)/(C3+C4+C5+C6+C7+C8+C9) -> 4.0909091 | AC16: =SUM(C10:C16)/7 -> 6.4285714 | AE16: =SUM(P10:P16)/7 -> 170.57143 | AF16: =SUM(Q10:Q16)/7 -> 0.041228571
A17: 43909 | B17: 73 | C17: 15 | D17: 1 | E17: 2 | F17: 2322 | G17: =F17/9.8 -> 236.93878 | H17: 124 | I17: 0.2586 | J17: 0.0314 | K17: 0.288 | L17: 70 | M17: 0.0137 | N17: 0.0274 | O17: 3065 | P17: 519 | Q17: 0.0289 | R17: 0 | S17: 0 | V17: =L17/B17 -> 0.95890411 | W17: =T17-T16 -> 0 | X17: =U17-U16 -> 0 | AA17: =(C11+C12+C13+C14+C15+C16+C17)/(C4+C5+C6+C7+C8+C9+C10) -> 4.75 | AC17: =SUM(C11:C17)/7 -> 8.1428571 | AE17: =SUM(P11:P17)/7 -> 227.42857 | AF17: =SUM(Q11:Q17)/7 -> 0.041814286 | AM17: =SUM(S11:S17)/7 -> 0.28571429
A18: 43910 | B18: 85 | C18: 12 | D18: 4 | E18: 7 | F18: 3007 | G18: =F18/9.8 -> 306.83673 | H18: 116 | I18: 0.1644 | J18: 0.0283 | K18: 0.295 | L18: 74 | M18: 0.0471 | N18: 0.0824 | O18: 3506 | P18: 685 | Q18: 0.0175 | R18: 3 | S18: 5 | V18: =L18/B18 -> 0.87058824 | W18: =T18-T17 -> 0 | X18: =U18-U17 -> 0 | AA18: =(C12+C13+C14+C15+C16+C17+C18)/(C5+C6+C7+C8+C9+C10+C11) -> 4.4 | AC18: =SUM(C12:C18)/7 -> 9.4285714 | AE18: =SUM(P12:P18)/7 -> 307 | AF18: =SUM(Q12:Q18)/7 -> 0.040971429 | AM18: =SUM(S12:S18)/7 -> 0.85714286
A19: 43911 | B19: 103 | C19: 18 | D19: 4 | E19: 7 | F19: 3477 | G19: =F19/9.8 -> 354.79592 | H19: 117 | I19: 0.2118 | J19: 0.0296 | K19: 0.156 | L19: 92 | M19: 0.0388 | N19: 0.068 | O19: 3771 | P19: 470 | Q19: 0.0383 | R19: 0 | S19: 0 | V19: =L19/B19 -> 0.89320388 | W19: =T19-T18 -> 0 | X19: =U19-U18 -> 0 | AA19: =(C13+C14+C15+C16+C17+C18+C19)/(C6+C7+C8+C9+C10+C11+C12) -> 2.92 | AC19: =SUM(C13:C19)/7 -> 10.428571 | AE19: =SUM(P13:P19)/7 -> 351.85714 | AF19: =SUM(Q13:Q19)/7 -> 0.036371429 | AM19: =SUM(S13:S19)/7 -> 0.85714286
A20: 43912 | B20: 131 | C20: 28 | D20: 6 | E20: 16 | F20: 4443 | G20: =F20/9.8 -> 453.36735 | H20: 115 | I20: 0.2718 | J20: 0.0295 | K20: 0.278 | L20: 109 | M20: 0.0458 | N20: 0.1221 | O20: 3945 | P20: 966 | Q20: 0.029 | R20: 2 | S20: 9 | V20: =L20/B20 -> 0.83206107 | W20: =T20-T19 -> 0 | X20: =U20-U19 -> 0 | AA20: =(C14+C15+C16+C17+C18+C19+C20)/(C7+C8+C9+C10+C11+C12+C13) -> 3.96 | AC20: =SUM(C14:C20)/7 -> 14.142857 | AD20: =SUM(R14:R20)/7 -> 0.85714286 | AE20: =SUM(P14:P20)/7 -> 458.14286 | AF20: =SUM(Q14:Q20)/7 -> 0.039228571 | AM20: =SUM(S14:S20)/7 -> 2.1428571
A21: 43913 | B21: 167 | C21: 36 | D21: 8 | E21: 21 | F21: 5515 | G21: =F21/9.8 -> 562.7551 | H21: 101 | I21: 0.2748 | J21: 0.0303 | K21: 0.241 | L21: 138 | M21: 0.0479 | N21: 0.1257 | O21: 4001 | P21: 1072 | Q21: 0.0336 | R21: 2 | S21: 5 | V21: =L21/B21 -> 0.82634731 | W21: =T21-T20 -> 0 | X21: =U21-U20 -> 0 | AA21: =(C15+C16+C17+C18+C19+C20+C21)/(C8+C9+C10+C11+C12+C13+C14) -> 4.2666667 | AB21: =SUM(AA15:AA21)/7 -> 3.9363203 | AC21: =SUM(C15:C21)/7 -> 18.285714 | AD21: =SUM(R15:R21)/7 -> 1 | AE21: =SUM(P15:P21)/7 -> 577.85714 | AF21: =SUM(Q15:Q21)/7 -> 0.039757143 | AM21: =SUM(S15:S21)/7 -> 2.7142857
A22: 43914 | B22: 187 | C22: 20 | D22: 9 | E22: 21 | F22: 6113 | G22: =F22/9.8 -> 623.77551 | H22: 92 | I22: 0.1198 | J22: 0.0306 | K22: 0.108 | L22: 157 | M22: 0.0481 | N22: 0.1123 | O22: 4207 | P22: 598 | Q22: 0.0334 | R22: 1 | S22: 0 | V22: =L22/B22 -> 0.83957219 | W22: =T22-T21 -> 0 | X22: =U22-U21 -> 0 | AA22: =(C16+C17+C18+C19+C20+C21+C22)/(C9+C10+C11+C12+C13+C14+C15) -> 3.6052632 | AB22: =SUM(AA16:AA22)/7 -> 3.998977 | AC22: =SUM(C16:C22)/7 -> 19.571429 | AD22: =SUM(R16:R22)/7 -> 1.1428571 | AE22: =SUM(P16:P22)/7 -> 646.57143 | AF22: =SUM(Q16:Q22)/7 -> 0.0311 | AM22: =SUM(S16:S22)/7 -> 2.7142857
A23: 43915 | B23: 226 | C23: 39 | D23: 10 | E23: 21 | F23: 6817 | G23: =F23/9.8 -> 695.61224 | H23: 85 | I23: 0.2086 | J23: 0.0332 | K23: 0.115 | L23: 195 | M23: 0.0442 | N23: 0.0929 | P23: 704 | Q23: 0.0554 | R23: 1 | S23: 0 | V23: =L23/B23 -> 0.86283186 | W23: =T23-T22 -> 0 | X23: =U23-U22 -> 0 | AA23: =(C17+C18+C19+C20+C21+C22+C23)/(C10+C11+C12+C13+C14+C15+C16) -> 3.7333333 | AB23: =SUM(AA17:AA23)/7 -> 3.9478947 | AC23: =SUM(C17:C23)/7 -> 24 | AD23: =SUM(R17:R23)/7 -> 1.2857143 | AE23: =SUM(P17:P23)/7 -> 716.28571 | AF23: =SUM(Q17:Q23)/7 -> 0.033728571 | AM23: =SUM(S17:S23)/7 -> 2.7142857
A24: 43916 | B24: 261 | C24: 35 | D24: 10 | E24: 28 | F24: 8005 | G24: =F24/9.8 -> 816.83673 | H24: 100 | I24: 0.1549 | J24: 0.0326 | K24: 0.174 | L24: 223 | M24: 0.0383 | N24: 0.1073 | P24: 1188 | Q24: 0.0295 | R24: 0 | S24: 7 | V24: =L24/B24 -> 0.85440613 | W24: =T24-T23 -> 0 | X24: =U24-U23 -> 0 | AA24: =(C18+C19+C20+C21+C22+C23+C24)/(C11+C12+C13+C14+C15+C16+C17) -> 3.2982456 | AB24: =SUM(AA18:AA24)/7 -> 3.7405013 | AC24: =SUM(C18:C24)/7 -> 26.857143 | AD24: =SUM(R18:R24)/7 -> 1.2857143 | AE24: =SUM(P18:P24)/7 -> 811.85714 | AF24: =SUM(Q18:Q24)/7 -> 0.033814286 | AM24: =SUM(S18:S24)/7 -> 3.7142857
A25: 43917 | B25: 300 | C25: 39 | D25: 10 | E25: 34 | F25: 9275 | G25: =F25/9.8 -> 946.42857 | H25: 84 | I25: 0.1494 | J25: 0.0323 | K25: 0.159 | L25: 256 | M25: 0.0333 | N25: 0.1133 | P25: 1270 | Q25: 0.0307 | R25: 0 | S25: 6 | V25: =L25/B25 -> 0.85333333 | W25: =T25-T24 -> 0 | X25: =U25-U24 -> 0 | AA25: =(C19+C20+C21+C22+C23+C24+C25)/(C12+C13+C14+C15+C16+C17+C18) -> 3.2575758 | AB25: =SUM(AA19:AA25)/7 -> 3.5772978 | AC25: =SUM(C19:C25)/7 -> 30.714286 | AD25: =SUM(R19:R25)/7 -> 0.85714286 | AE25: =SUM(P19:P25)/7 -> 895.42857 | AF25: =SUM(Q19:Q25)/7 -> 0.0357 | AM25: =SUM(S19:S25)/7 -> 3.8571429
A26: 43918 | B26: 343 | C26: 43 | D26: 11 | E26: 34 | F26: 10303 | G26: =F26/9.8 -> 1051.3265 | H26: 87 | I26: 0.1433 | J26: 0.0333 | K26: 0.111 | L26: 298 | M26: 0.0321 | N26: 0.0991 | P26: 1028 | Q26: 0.0418 | R26: 1 | S26: 0 | V26: =L26/B26 -> 0.86880466 | W26: =T26-T25 -> 0 | X26: =U26-U25 -> 0 | AA26: =(C20+C21+C22+C23+C24+C25+C26)/(C13+C14+C15+C16+C17+C18+C19) -> 3.2876712 | AB26: =SUM(AA20:AA26)/7 -> 3.6298223 | AC26: =SUM(C20:C26)/7 -> 34.285714 | AD26: =SUM(R20:R26)/7 -> 1 | AE26: =SUM(P20:P26)/7 -> 975.14286 | AF26: =SUM(Q20:Q26)/7 -> 0.0362 | AM26: =SUM(S20:S26)/7 -> 3.8571429
A27: 43919 | B27: 408 | C27: 65 | D27: 13 | E27: 34 | F27: 12148 | G27: =F27/9.8 -> 1239.5918 | H27: 71 | I27: 0.1895 | J27: 0.0336 | K27: 0.179 | L27: 361 | M27: 0.0319 | N27: 0.0833 | P27: 1845 | Q27: 0.0352 | R27: 2 | S27: 0 | V27: =L27/B27 -> 0.88480392 | W27: =T27-T26 -> 0 | X27: =U27-U26 -> 0 | AA27: =(C21+C22+C23+C24+C25+C26+C27)/(C14+C15+C16+C17+C18+C19+C20) -> 2.7979798 | AB27: =SUM(AA21:AA27)/7 -> 3.4638194 | AC27: =SUM(C21:C27)/7 -> 39.571429 | AD27: =SUM(R21:R27)/7 -> 1 | AE27: =SUM(P21:P27)/7 -> 1100.7143 | AF27: =SUM(Q21:Q27)/7 -> 0.037085714 | AM27: =SUM(S21:S27)/7 -> 2.5714286
A28: 43920 | B28: 447 | C28: 39 | D28: 15 | E28: 34 | F28: 13301 | G28: =F28/9.8 -> 1357.2449 | H28: 73 | I28: 0.0956 | J28: 0.0336 | K28: 0.095 | L28: 398 | M28: 0.0336 | N28: 0.0761 | P28: 1153 | Q28: 0.0338 | R28: 2 | S28: 0 | V28: =L28/B28 -> 0.89038031 | W28: =T28-T27 -> 0 | X28: =U28-U27 -> 0 | AA28: =(C22+C23+C24+C25+C26+C27+C28)/(C15+C16+C17+C18+C19+C20+C21) -> 2.1875 | AB28: =SUM(AA22:AA28)/7 -> 3.1667956 | AC28: =SUM(C22:C28)/7 -> 40 | AD28: =SUM(R22:R28)/7 -> 1 | AE28: =SUM(P22:P28)/7 -> 1112.2857 | AF28: =SUM(Q22:Q28)/7 -> 0.037114286 | AM28: =SUM(S22:S28)/7 -> 1.8571429
A29: 43921 | B29: 492 | C29: 45 | D29: 16 | E29: 37 | F29: 14146 | G29: =F29/9.8 -> 1443.4694 | H29: 61 | I29: 0.1007 | J29: 0.0348 | K29: 0.064 | L29: 439 | M29: 0.0325 | N29: 0.0752 | P29: 845 | Q29: 0.0533 | R29: 2 | S29: 3 | V29: =L29/B29 -> 0.89227642 | W29: =T29-T28 -> 0 | X29: =U29-U28 -> 0 | AA29: =(C23+C24+C25+C26+C27+C28+C29)/(C16+C17+C18+C19+C20+C21+C22) -> 2.2262774 | AB29: =SUM(AA23:AA29)/7 -> 2.9697976 | AC29: =SUM(C23:C29)/7 -> 43.571429 | AD29: =SUM(R23:R29)/7 -> 1.1428571 | AE29: =SUM(P23:P29)/7 -> 1147.5714 | AF29: =SUM(Q23:Q29)/7 -> 0.039957143 | AM29: =SUM(S23:S29)/7 -> 2.2857143
A30: 43922 | B30: 525 | C30: 33 | D30: 20 | E30: 40 | F30: 15208 | G30: =F30/9.8 -> 1551.8367 | H30: 61 | I30: 0.0671 | J30: 0.0345 | K30: 0.075 | L30: 465 | M30: 0.0381 | N30: 0.0762 | P30: 1062 | Q30: 0.0311 | R30: 4 | S30: 3 | V30: =L30/B30 -> 0.88571429 | W30: =T30-T29 -> 0 | X30: =U30-U29 -> 0 | AA30: =(C24+C25+C26+C27+C28+C29+C30)/(C17+C18+C19+C20+C21+C22+C23) -> 1.7797619 | AB30: =SUM(AA24:AA30)/7 -> 2.690716 | AC30: =SUM(C24:C30)/7 -> 42.714286 | AD30: =SUM(R24:R30)/7 -> 1.5714286 | AE30: =SUM(P24:P30)/7 -> 1198.7143 | AF30: =SUM(Q24:Q30)/7 -> 0.036485714 | AM30: =SUM(S24:S30)/7 -> 2.7142857
A31: 43923 | B31: 585 | C31: 60 | D31: 21 | E31: 42 | F31: 16401 | G31: =F31/9.8 -> 1673.5714 | H31: 59 | I31: 0.1143 | J31: 0.0357 | K31: 0.078 | L31: 522 | M31: 0.0359 | N31: 0.0718 | P31: 1193 | Q31: 0.0503 | R31: 1 | S31: 2 | V31: =L31/B31 -> 0.89230769 | W31: =T31-T30 -> 0 | X31: =U31-U30 -> 0 | AA31: =(C25+C26+C27+C28+C29+C30+C31)/(C18+C19+C20+C21+C22+C23+C24) -> 1.7234043 | AB31: =SUM(AA25:AA31)/7 -> 2.4657386 | AC31: =SUM(C25:C31)/7 -> 46.285714 | AD31: =SUM(R25:R31)/7 -> 1.7142857 | AE31: =SUM(P25:P31)/7 -> 1199.4286 | AF31: =SUM(Q25:Q31)/7 -> 0.039457143 | AM31: =SUM(S25:S31)/7 -> 2
A32: 43924 | B32: 623 | C32: 38 | D32: 26 | E32: 43 | F32: 17769 | G32: =F32/9.8 -> 1813.1633 | I32: 0.065 | J32: 0.0351 | K32: 0.083 | L32: 554 | M32: 0.0417 | N32: 0.069 | O32: 10668 | P32: 1368 | Q32: 0.0278 | R32: 5 | S32: 1 | V32: =L32/B32 -> 0.88924559 | W32: =T32-T31 -> 0 | X32: =U32-U31 -> 0 | AA32: =(C26+C27+C28+C29+C30+C31+C32)/(C19+C20+C21+C22+C23+C24+C25) -> 1.5023256 | AB32: =SUM(AA26:AA32)/7 -> 2.2149886 | AC32: =SUM(C26:C32)/7 -> 46.142857 | AD32: =SUM(R26:R32)/7 -> 2.4285714 | AE32: =SUM(P26:P32)/7 -> 1213.4286 | AF32: =SUM(Q26:Q32)/7 -> 0.039042857 | AM32: =SUM(S26:S32)/7 -> 1.2857143
A33: 43925 | B33: 678 | C33: 55 | D33: 32 | E33: 58 | F33: 19424 | G33: =F33/9.8 -> 1982.0408 | I33: 0.0883 | J33: 0.0349 | K33: 0.093 | L33: 588 | M33: 0.0472 | N33: 0.0855 | O33: 12492 | P33: 1655 | Q33: 0.0332 | R33: 6 | S33: 15 | V33: =L33/B33 -> 0.86725664 | W33: =T33-T32 -> 0 | X33: =U33-U32 -> 0 | AA33: =(C27+C28+C29+C30+C31+C32+C33)/(C20+C21+C22+C23+C24+C25+C26) -> 1.3958333 | AB33: =SUM(AA27:AA33)/7 -> 1.944726 | AC33: =SUM(C27:C33)/7 -> 47.857143 | AD33: =SUM(R27:R33)/7 -> 3.1428571 | AE33: =SUM(P27:P33)/7 -> 1303 | AF33: =SUM(Q27:Q33)/7 -> 0.037814286 | AM33: =SUM(S27:S33)/7 -> 3.4285714
A34: 43926 | B34: 733 | C34: 55 | D34: 34 | E34: 66 | F34: 21250 | G34: =F34/9.8 -> 2168.3673 | I34: 0.0811 | J34: 0.0345 | K34: 0.094 | L34: 633 | M34: 0.0464 | N34: 0.09 | O34: 13435 | P34: 1826 | Q34: 0.0301 | R34: 2 | S34: 8 | V34: =L34/B34 -> 0.86357435 | W34: =T34-T33 -> 0 | X34: =U34-U33 -> 0 | AA34: =(C28+C29+C30+C31+C32+C33+C34)/(C21+C22+C23+C24+C25+C26+C27) -> 1.1732852 | AB34: =SUM(AA28:AA34)/7 -> 1.7126268 | AC34: =SUM(C28:C34)/7 -> 46.428571 | AD34: =SUM(R28:R34)/7 -> 3.1428571 | AE34: =SUM(P28:P34)/7 -> 1300.2857 | AF34: =SUM(Q28:Q34)/7 -> 0.037085714 | AM34: =SUM(S28:S34)/7 -> 4.5714286
A35: 43927 | B35: 744 | C35: 11 | D35: 38 | E35: 67 | F35: 22282 | G35: =F35/9.8 -> 2273.6735 | I35: 0.015 | J35: 0.0334 | K35: 0.049 | L35: 639 | M35: 0.0511 | N35: 0.0901 | O35: 14345 | P35: 1032 | Q35: 0.0107 | R35: 4 | S35: 1 | V35: =L35/B35 -> 0.85887097 | W35: =T35-T34 -> 0 | X35: =U35-U34 -> 0 | AA35: =(C29+C30+C31+C32+C33+C34+C35)/(C22+C23+C24+C25+C26+C27+C28) -> 1.0607143 | AB35: =SUM(AA29:AA35)/7 -> 1.5516574 | AC35: =SUM(C29:C35)/7 -> 42.428571 | AD35: =SUM(R29:R35)/7 -> 3.4285714 | AE35: =SUM(P29:P35)/7 -> 1283 | AF35: =SUM(Q29:Q35)/7 -> 0.033785714 | AM35: =SUM(S29:S35)/7 -> 4.7142857
A36: 43928 | B36: 817 | C36: 73 | D36: 47 | E36: 71 | F36: 23746 | G36: =F36/9.8 -> 2423.0612 | I36: 0.0981 | J36: 0.0344 | K36: 0.066 | L36: 699 | M36: 0.0575 | N36: 0.0869 | O36: 14997 | P36: 1464 | Q36: 0.0499 | R36: 9 | S36: 4 | V36: =L36/B36 -> 0.85556916 | W36: =T36-T35 -> 0 | X36: =U36-U35 -> 0 | AA36: =(C30+C31+C32+C33+C34+C35+C36)/(C23+C24+C25+C26+C27+C28+C29) -> 1.0655738 | AB36: =SUM(AA30:AA36)/7 -> 1.3858426 | AC36: =SUM(C30:C36)/7 -> 46.428571 | AD36: =SUM(R30:R36)/7 -> 4.4285714 | AE36: =SUM(P30:P36)/7 -> 1371.4286 | AF36: =SUM(Q30:Q36)/7 -> 0.0333 | AM36: =SUM(S30:S36)/7 -> 4.8571429
A37: 43929 | B37: 895 | C37: 78 | D37: 58 | E37: 94 | F37: 25748 | G37: =F37/9.8 -> 2627.3469 | I37: 0.0955 | J37: 0.0348 | K37: 0.084 | L37: 743 | M37: 0.0648 | N37: 0.105 | O37: 15481 | P37: 2002 | Q37: 0.039 | R37: 11 | S37: 23 | V37: =L37/B37 -> 0.8301676 | W37: =T37-T36 -> 0 | X37: =U37-U36 -> 0 | AA37: =(C31+C32+C33+C34+C35+C36+C37)/(C24+C25+C26+C27+C28+C29+C30) -> 1.2374582 | AB37: =SUM(AA31:AA37)/7 -> 1.3083707 | AC37: =SUM(C31:C37)/7 -> 52.857143 | AD37: =SUM(R31:R37)/7 -> 5.4285714 | AE37: =SUM(P31:P37)/7 -> 1505.7143 | AF37: =SUM(Q31:Q37)/7 -> 0.034428571 | AM37: =SUM(S31:S37)/7 -> 7.7142857
A38: 43930 | B38: 980 | C38: 85 | D38: 66 | E38: 96 | F38: 27826 | G38: =F38/9.8 -> 2839.3878 | I38: 0.095 | J38: 0.0352 | K38: 0.081 | L38: 818 | M38: 0.0673 | N38: 0.098 | O38: 16006 | P38: 2078 | Q38: 0.0409 | R38: 8 | S38: 2 | V38: =L38/B38 -> 0.83469388 | W38: =T38-T37 -> 0 | X38: =U38-U37 -> 0 | AA38: =(C32+C33+C34+C35+C36+C37+C38)/(C25+C26+C27+C28+C29+C30+C31) -> 1.2191358 | AB38: =SUM(AA32:AA38)/7 -> 1.2363323 | AC38: =SUM(C32:C38)/7 -> 56.428571 | AD38: =SUM(R32:R38)/7 -> 6.4285714 | AE38: =SUM(P32:P38)/7 -> 1632.1429 | AF38: =SUM(Q32:Q38)/7 -> 0.033085714 | AM38: =SUM(S32:S38)/7 -> 7.7142857
A39: 43931 | B39: 1190 | C39: 210 | D39: 77 | E39: 112 | F39: 29948 | G39: =F39/9.8 -> 3055.9184 | I39: 0.2143 | J39: 0.0397 | K39: 0.076 | L39: 1001 | M39: 0.0647 | N39: 0.0941 | O39: 16006 | P39: 2122 | Q39: 0.099 | R39: 11 | S39: 16 | V39: =L39/B39 -> 0.84117647 | W39: =T39-T38 -> 0 | X39: =U39-U38 -> 0 | AA39: =(C33+C34+C35+C36+C37+C38+C39)/(C26+C27+C28+C29+C30+C31+C32) -> 1.755418 | AB39: =SUM(AA33:AA39)/7 -> 1.2724884 | AC39: =SUM(C33:C39)/7 -> 81 | AD39: =SUM(R33:R39)/7 -> 7.2857143 | AE39: =SUM(P33:P39)/7 -> 1739.8571 | AF39: =SUM(Q33:Q39)/7 -> 0.043257143 | AM39: =SUM(S33:S39)/7 -> 9.8571429
A40: 43932 | B40: 1310 | C40: 120 | D40: 85 | E40: 115 | F40: 31961 | G40: =F40/9.8 -> 3261.3265 | I40: 0.1008 | J40: 0.041 | K40: 0.067 | L40: 1110 | M40: 0.0649 | N40: 0.0878 | O40: 17490 | P40: 2013 | Q40: 0.0596 | R40: 8 | S40: 3 | V40: =L40/B40 -> 0.84732824 | W40: =T40-T39 -> 0 | X40: =U40-U39 -> 0 | AA40: =(C34+C35+C36+C37+C38+C39+C40)/(C27+C28+C29+C30+C31+C32+C33) -> 1.8865672 | AB40: =SUM(AA34:AA40)/7 -> 1.3425932 | AC40: =SUM(C34:C40)/7 -> 90.285714 | AD40: =SUM(R34:R40)/7 -> 7.5714286 | AE40: =SUM(P34:P40)/7 -> 1791 | AF40: =SUM(Q34:Q40)/7 -> 0.047028571 | AM40: =SUM(S34:S40)/7 -> 8.1428571
...

Sheet tabla
A1: Dátum | B1: Regisztrált esetek száma | C1: Új esetek száma | D1: Elhunytak | E1: Gyógyultak | F1: Mintavétel száma | G1: Egymillió lakosra elvégzett tesztek száma | H1: Kórházi karanténba zártak száma | I1: Regisztrált esetek százalékos változása az előző naphoz viszonyítva | J1: Pozitív tesztek aránya | K1: A mintavételek számának százalékos változása az előző naphoz képest | L1: Aktív fertőzöttek száma | M1: Elhunytak aránya Magyarországon | N1: Gyógyultak aránya Magyarországon | O1: Hatósági házi karantén | P1: Új mintavételek száma | Q1: Új esetek aránya az új mintavételekhez képest | R1: Új elhunytak száma | S1: Új gyógyultak száma | T1: Kórházi ápoltak száma | U1: Lélegeztetőgépen lévők száma | V1: Aktív esetek/összes eset | W1: Kórházi ápoltak számának változása az előző naphoz képest | X1: Lélegeztetőgépen lévők számának változása az előző naphoz képest | Y1: Kórházi ápoltak aránya az aktív eseteken belül | Z1: Lélegeztetőgépen lévők aránya a kórházi ápoltakon belül | AA1: Növekedési faktor | AB1: Hétnapos mozgóátlag | AC1: Hétnapos csúszóátlag | AD1: Hétnapos csúszóátlag | AE1: Hétnapos csúszóátlag | AF1: Hétnapos csúszóátlag | AG1: Beoltottak száma Magyarországon | AH1: Új beoltottak száma Magyarországon | AI1: Hétnapos csúszóátlag | AJ1: Második oltás | AK1: Második oltás napi | AL1: Hétnapos csúszóátlag | AM1: Hétnapos csúszóátlag | AN1: =IFERROR(__xludf.DUMMYFUNCTION("unique(koronahun!A:A)"),"Dátum") -> Dátum | AO1: Regeset | AP1: Dátum | AQ1: =IFERROR(__xludf.DUMMYFUNCTION("unique(AP:AP)"),"Dátum") -> Dátum | AR1: Dátum | AS1: Dátum | AT1: =IFERROR(__xludf.DUMMYFUNCTION("unique(AS:AS)"),"Dátum") -> Dátum
A2: 44923 | B2: =IFERROR(VLOOKUP($A2,koronahun!$A:$AM,2,FALSE),"") -> 2185816 | C2: =IFERROR(VLOOKUP($A2,koronahun!$A:$AM,3,FALSE),"") -> 4397 | D2: =IFERROR(VLOOKUP($A2,koronahun!$A:$AM,4,FALSE),"") -> 48495 | E2: =IFERROR(VLOOKUP($A2,koronahun!$A:$AM,5,FALSE),"") -> 2123750 | F2: =IFERROR(VLOOKUP($A2,koronahun!$A:$AM,6,FALSE),"") -> 11394556 | G2: =IFERROR(VLOOKUP($A2,koronahun!$A:$AM,7,FALSE),"") -> 1162709.8 | H2: =IFERROR(VLOOKUP($A2,koronahun!$A:$AM,8,FALSE),"") -> 0 | I2: =IFERROR(VLOOKUP($A2,koronahun!$A:$AM,9,FALSE),"") -> 0.0020156604 | J2: =IFERROR(VLOOKUP($A2,koronahun!$A:$AM,10,FALSE),"") -> 0.19182985 | K2: =IFERROR(VLOOKUP($A2,koronahun!$A:$AM,11,FALSE),"") -> 0 | L2: =IFERROR(VLOOKUP($A2,koronahun!$A:$AM,12,FALSE),"") -> 13571 | M2: =IFERROR(VLOOKUP($A2,koronahun!$A:$AM,13,FALSE),"") -> 0.022186222 | N2: =IFERROR(VLOOKUP($A2,koronahun!$A:$AM,14,FALSE),"") -> 0.97160511 | O2: =IFERROR(VLOOKUP($A2,koronahun!$A:$AM,15,FALSE),"") -> 0 | P2: =IFERROR(VLOOKUP($A2,koronahun!$A:$AM,16,FALSE),"") -> 0 | Q2: =IFERROR(VLOOKUP($A2,koronahun!$A:$AM,17,FALSE),"") -> 0 | R2: =IFERROR(VLOOKUP($A2,koronahun!$A:$AM,18,FALSE),"") -> 56 | S2: =IFERROR(VLOOKUP($A2,koronahun!$A:$AM,19,FALSE),"") -> 4839 | T2: =IFERROR(VLOOKUP($A2,koronahun!$A:$AM,20,FALSE),"") -> 386 | U2: =IFERROR(VLOOKUP($A2,koronahun!$A:$AM,21,FALSE),"") -> 9 | V2: =IFERROR(VLOOKUP($A2,koronahun!$A:$AM,22,FALSE),"") -> 0.0062086653 | W2: =IFERROR(VLOOKUP($A2,koronahun!$A:$AM,23,FALSE),"") -> 1345 | X2: =IFERROR(VLOOKUP($A2,koronahun!$A:$AM,24,FALSE),"") -> 19 | Y2: =IFERROR(VLOOKUP($A2,koronahun!$A:$AM,25,FALSE),"") -> 0.028443003 | Z2: =IFERROR(VLOOKUP($A2,koronahun!$A:$AM,26,FALSE),"") -> 0.023316062 | AA2: =IFERROR(VLOOKUP($A2,koronahun!$A:$AM,27,FALSE),"") -> 0.85048356 | AB2: =IFERROR(VLOOKUP($A2,koronahun!$A:$AM,28,FALSE),"") -> 0 | AC2: =IFERROR(VLOOKUP($A2,koronahun!$A:$AM,29,FALSE),"") -> 628.14286 | AD2: =IFERROR(VLOOKUP($A2,koronahun!$A:$AM,30,FALSE),"") -> 8 | AE2: =IFERROR(VLOOKUP($A2,koronahun!$A:$AM,31,FALSE),"") -> 0 | AF2: =IFERROR(VLOOKUP($A2,koronahun!$A:$AM,32,FALSE),"") -> 0 | AG2: =IFERROR(VLOOKUP($A2,koronahun!$A:$AM,33,FALSE),"") -> 6420813 | AH2: =IFERROR(VLOOKUP($A2,koronahun!$A:$AM,34,FALSE),"") -> 113 | AI2: =IFERROR(VLOOKUP($A2,koronahun!$A:$AM,35,FALSE),"") -> 16.142857 | AJ2: =IFERROR(VLOOKUP($A2,koronahun!$A:$AM,36,FALSE),"") -> 6207249 | AK2: =IFERROR(VLOOKUP($A2,koronahun!$A:$AM,37,FALSE),"") -> 216 | AL2: =IFERROR(VLOOKUP($A2,koronahun!$A:$AM,38,FALSE),"") -> 30.857143 | AM2: =IFERROR(VLOOKUP($A2,koronahun!$A:$AM,39,FALSE),"") -> 691.28571 | AN2: =IFERROR(__xludf.DUMMYFUNCTION("""COMPUTED_VALUE"""),43894) -> 43894 | AO2: =IFERROR(VLOOKUP(AN2,koronahun!A:B,2,FALSE),"") -> 2 | AP2: =IF(AO2="","",AN2) -> 43894 | AQ2: =IFERROR(__xludf.DUMMYFUNCTION("""COMPUTED_VALUE"""),43894) -> 43894 | AS2: =IF(AR2="",AR3,AR2) -> 44923 | AT2: =IFERROR(__xludf.DUMMYFUNCTION("""COMPUTED_VALUE"""),44923) -> 44923
A3: 44916 | B3: =IFERROR(VLOOKUP($A3,koronahun!$A:$AM,2,FALSE),"") -> 2181419 | C3: =IFERROR(VLOOKUP($A3,koronahun!$A:$AM,3,FALSE),"") -> 5170 | D3: =IFERROR(VLOOKUP($A3,koronahun!$A:$AM,4,FALSE),"") -> 48439 | E3: =IFERROR(VLOOKUP($A3,koronahun!$A:$AM,5,FALSE),"") -> 2118911 | F3: =IFERROR(VLOOKUP($A3,koronahun!$A:$AM,6,FALSE),"") -> 11394556 | G3: =IFERROR(VLOOKUP($A3,koronahun!$A:$AM,7,FALSE),"") -> 1162709.8 | H3: =IFERROR(VLOOKUP($A3,koronahun!$A:$AM,8,FALSE),"") -> 0 | I3: =IFERROR(VLOOKUP($A3,koronahun!$A:$AM,9,FALSE),"") -> 0.0023756473 | J3: =IFERROR(VLOOKUP($A3,koronahun!$A:$AM,10,FALSE),"") -> 0.19144397 | K3: =IFERROR(VLOOKUP($A3,koronahun!$A:$AM,11,FALSE),"") -> 0 | L3: =IFERROR(VLOOKUP($A3,koronahun!$A:$AM,12,FALSE),"") -> 14069 | M3: =IFERROR(VLOOKUP($A3,koronahun!$A:$AM,13,FALSE),"") -> 0.022205271 | N3: =IFERROR(VLOOKUP($A3,koronahun!$A:$AM,14,FALSE),"") -> 0.97134526 | O3: =IFERROR(VLOOKUP($A3,koronahun!$A:$AM,15,FALSE),"") -> 0 | P3: =IFERROR(VLOOKUP($A3,koronahun!$A:$AM,16,FALSE),"") -> 0 | Q3: =IFERROR(VLOOKUP($A3,koronahun!$A:$AM,17,FALSE),"") -> 0 | R3: =IFERROR(VLOOKUP($A3,koronahun!$A:$AM,18,FALSE),"") -> 59 | S3: =IFERROR(VLOOKUP($A3,koronahun!$A:$AM,19,FALSE),"") -> 4777 | T3: =IFERROR(VLOOKUP($A3,koronahun!$A:$AM,20,FALSE),"") -> 1044 | U3: =IFERROR(VLOOKUP($A3,koronahun!$A:$AM,21,FALSE),"") -> 16 | V3: =IFERROR(VLOOKUP($A3,koronahun!$A:$AM,22,FALSE),"") -> 0.0064494717 | W3: =IFERROR(VLOOKUP($A3,koronahun!$A:$AM,23,FALSE),"") -> 1345 | X3: =IFERROR(VLOOKUP($A3,koronahun!$A:$AM,24,FALSE),"") -> 19 | Y3: =IFERROR(VLOOKUP($A3,koronahun!$A:$AM,25,FALSE),"") -> 0.0742057 | Z3: =IFERROR(VLOOKUP($A3,koronahun!$A:$AM,26,FALSE),"") -> 0.01532567 | AA3: =IFERROR(VLOOKUP($A3,koronahun!$A:$AM,27,FALSE),"") -> 0.99557096 | AB3: =IFERROR(VLOOKUP($A3,koronahun!$A:$AM,28,FALSE),"") -> 0 | AC3: =IFERROR(VLOOKUP($A3,koronahun!$A:$AM,29,FALSE),"") -> 738.57143 | AD3: =IFERROR(VLOOKUP($A3,koronahun!$A:$AM,30,FALSE),"") -> 8.4285714 | AE3: =IFERROR(VLOOKUP($A3,koronahun!$A:$AM,31,FALSE),"") -> 0 | AF3: =IFERROR(VLOOKUP($A3,koronahun!$A:$AM,32,FALSE),"") -> 0 | AG3: =IFERROR(VLOOKUP($A3,koronahun!$A:$AM,33,FALSE),"") -> 6420700 | AH3: =IFERROR(VLOOKUP($A3,koronahun!$A:$AM,34,FALSE),"") -> 154 | AI3: =IFERROR(VLOOKUP($A3,koronahun!$A:$AM,35,FALSE),"") -> 22 | AJ3: =IFERROR(VLOOKUP($A3,koronahun!$A:$AM,36,FALSE),"") -> 6207033 | AK3: =IFERROR(VLOOKUP($A3,koronahun!$A:$AM,37,FALSE),"") -> 155 | AL3: =IFERROR(VLOOKUP($A3,koronahun!$A:$AM,38,FALSE),"") -> 22.142857 | AM3: =IFERROR(VLOOKUP($A3,koronahun!$A:$AM,39,FALSE),"") -> 682.42857 | AN3: =IFERROR(__xludf.DUMMYFUNCTION("""COMPUTED_VALUE"""),43895) -> 43895 | AO3: =IFERROR(VLOOKUP(AN3,koronahun!A:B,2,FALSE),"") -> 4 | AP3: =IF(AO3="","",AN3) -> 43895 | AQ3: =IFERROR(__xludf.DUMMYFUNCTION("""COMPUTED_VALUE"""),43895) -> 43895 | AR3: 44923 | AS3: =IF(AR3="",AR4,AR3) -> 44923 | AT3: =IFERROR(__xludf.DUMMYFUNCTION("""COMPUTED_VALUE"""),44916) -> 44916
A4: 44909 | B4: =IFERROR(VLOOKUP($A4,koronahun!$A:$AM,2,FALSE),"") -> 2176249 | C4: =IFERROR(VLOOKUP($A4,koronahun!$A:$AM,3,FALSE),"") -> 5193 | D4: =IFERROR(VLOOKUP($A4,koronahun!$A:$AM,4,FALSE),"") -> 48380 | E4: =IFERROR(VLOOKUP($A4,koronahun!$A:$AM,5,FALSE),"") -> 2114134 | F4: =IFERROR(VLOOKUP($A4,koronahun!$A:$AM,6,FALSE),"") -> 11394556 | G4: =IFERROR(VLOOKUP($A4,koronahun!$A:$AM,7,FALSE),"") -> 1162709.8 | H4: =IFERROR(VLOOKUP($A4,koronahun!$A:$AM,8,FALSE),"") -> 0 | I4: =IFERROR(VLOOKUP($A4,koronahun!$A:$AM,9,FALSE),"") -> 0.0023919236 | J4: =IFERROR(VLOOKUP($A4,koronahun!$A:$AM,10,FALSE),"") -> 0.19099024 | K4: =IFERROR(VLOOKUP($A4,koronahun!$A:$AM,11,FALSE),"") -> 0 | L4: =IFERROR(VLOOKUP($A4,koronahun!$A:$AM,12,FALSE),"") -> 13735 | M4: =IFERROR(VLOOKUP($A4,koronahun!$A:$AM,13,FALSE),"") -> 0.022230912 | N4: =IFERROR(VLOOKUP($A4,koronahun!$A:$AM,14,FALSE),"") -> 0.97145777 | O4: =IFERROR(VLOOKUP($A4,koronahun!$A:$AM,15,FALSE),"") -> 0 | P4: =IFERROR(VLOOKUP($A4,koronahun!$A:$AM,16,FALSE),"") -> 0 | Q4: =IFERROR(VLOOKUP($A4,koronahun!$A:$AM,17,FALSE),"") -> 0 | R4: =IFERROR(VLOOKUP($A4,koronahun!$A:$AM,18,FALSE),"") -> 43 | S4: =IFERROR(VLOOKUP($A4,koronahun!$A:$AM,19,FALSE),"") -> 4499 | T4: =IFERROR(VLOOKUP($A4,koronahun!$A:$AM,20,FALSE),"") -> 1124 | U4: =IFERROR(VLOOKUP($A4,koronahun!$A:$AM,21,FALSE),"") -> 24 | V4: =IFERROR(VLOOKUP($A4,koronahun!$A:$AM,22,FALSE),"") -> 0.0063113182 | W4: =IFERROR(VLOOKUP($A4,koronahun!$A:$AM,23,FALSE),"") -> 1345 | X4: =IFERROR(VLOOKUP($A4,koronahun!$A:$AM,24,FALSE),"") -> 19 | Y4: =IFERROR(VLOOKUP($A4,koronahun!$A:$AM,25,FALSE),"") -> 0.081834729 | Z4: =IFERROR(VLOOKUP($A4,koronahun!$A:$AM,26,FALSE),"") -> 0.021352313 | AA4: =IFERROR(VLOOKUP($A4,koronahun!$A:$AM,27,FALSE),"") -> 1.1039541 | AB4: =IFERROR(VLOOKUP($A4,koronahun!$A:$AM,28,FALSE),"") -> 0 | AC4: =IFERROR(VLOOKUP($A4,koronahun!$A:$AM,29,FALSE),"") -> 741.85714 | AD4: =IFERROR(VLOOKUP($A4,koronahun!$A:$AM,30,FALSE),"") -> 6.1428571 | AE4: =IFERROR(VLOOKUP($A4,koronahun!$A:$AM,31,FALSE),"") -> 0 | AF4: =IFERROR(VLOOKUP($A4,koronahun!$A:$AM,32,FALSE),"") -> 0 | AG4: =IFERROR(VLOOKUP($A4,koronahun!$A:$AM,33,FALSE),"") -> 6420546 | AH4: =IFERROR(VLOOKUP($A4,koronahun!$A:$AM,34,FALSE),"") -> 192 | AI4: =IFERROR(VLOOKUP($A4,koronahun!$A:$AM,35,FALSE),"") -> 27.428571 | AJ4: =IFERROR(VLOOKUP($A4,koronahun!$A:$AM,36,FALSE),"") -> 6206878 | AK4: =IFERROR(VLOOKUP($A4,koronahun!$A:$AM,37,FALSE),"") -> 168 | AL4: =IFERROR(VLOOKUP($A4,koronahun!$A:$AM,38,FALSE),"") -> 24 | AM4: =IFERROR(VLOOKUP($A4,koronahun!$A:$AM,39,FALSE),"") -> 642.71429 | AN4: =IFERROR(__xludf.DUMMYFUNCTION("""COMPUTED_VALUE"""),43896) -> 43896 | AO4: =IFERROR(VLOOKUP(AN4,koronahun!A:B,2,FALSE),"") -> 4 | AP4: =IF(AO4="","",AN4) -> 43896 | AQ4: =IFERROR(__xludf.DUMMYFUNCTION("""COMPUTED_VALUE"""),43896) -> 43896 | AR4: 44916 | AS4: =IF(AR4="",AR5,AR4) -> 44916 | AT4: =IFERROR(__xludf.DUMMYFUNCTION("""COMPUTED_VALUE"""),44909) -> 44909
A5: 44902 | B5: =IFERROR(VLOOKUP($A5,koronahun!$A:$AM,2,FALSE),"") -> 2171056 | C5: =IFERROR(VLOOKUP($A5,koronahun!$A:$AM,3,FALSE),"") -> 4704 | D5: =IFERROR(VLOOKUP($A5,koronahun!$A:$AM,4,FALSE),"") -> 48337 | E5: =IFERROR(VLOOKUP($A5,koronahun!$A:$AM,5,FALSE),"") -> 2109635 | F5: =IFERROR(VLOOKUP($A5,koronahun!$A:$AM,6,FALSE),"") -> 11394556 | G5: =IFERROR(VLOOKUP($A5,koronahun!$A:$AM,7,FALSE),"") -> 1162709.8 | H5: =IFERROR(VLOOKUP($A5,koronahun!$A:$AM,8,FALSE),"") -> 0 | I5: =IFERROR(VLOOKUP($A5,koronahun!$A:$AM,9,FALSE),"") -> 0.0021713923 | J5: =IFERROR(VLOOKUP($A5,koronahun!$A:$AM,10,FALSE),"") -> 0.1905345 | K5: =IFERROR(VLOOKUP($A5,koronahun!$A:$AM,11,FALSE),"") -> 0 | L5: =IFERROR(VLOOKUP($A5,koronahun!$A:$AM,12,FALSE),"") -> 13084 | M5: =IFERROR(VLOOKUP($A5,koronahun!$A:$AM,13,FALSE),"") -> 0.022264281 | N5: =IFERROR(VLOOKUP($A5,koronahun!$A:$AM,14,FALSE),"") -> 0.97170916 | O5: =IFERROR(VLOOKUP($A5,koronahun!$A:$AM,15,FALSE),"") -> 0 | P5: =IFERROR(VLOOKUP($A5,koronahun!$A:$AM,16,FALSE),"") -> 0 | Q5: =IFERROR(VLOOKUP($A5,koronahun!$A:$AM,17,FALSE),"") -> 0 | R5: =IFERROR(VLOOKUP($A5,koronahun!$A:$AM,18,FALSE),"") -> 50 | S5: =IFERROR(VLOOKUP($A5,koronahun!$A:$AM,19,FALSE),"") -> 5277 | T5: =IFERROR(VLOOKUP($A5,koronahun!$A:$AM,20,FALSE),"") -> 828 | U5: =IFERROR(VLOOKUP($A5,koronahun!$A:$AM,21,FALSE),"") -> 14 | V5: =IFERROR(VLOOKUP($A5,koronahun!$A:$AM,22,FALSE),"") -> 0.0060265603 | W5: =IFERROR(VLOOKUP($A5,koronahun!$A:$AM,23,FALSE),"") -> 1345 | X5: =IFERROR(VLOOKUP($A5,koronahun!$A:$AM,24,FALSE),"") -> 19 | Y5: =IFERROR(VLOOKUP($A5,koronahun!$A:$AM,25,FALSE),"") -> 0.0632834 | Z5: =IFERROR(VLOOKUP($A5,koronahun!$A:$AM,26,FALSE),"") -> 0.016908213 | AA5: =IFERROR(VLOOKUP($A5,koronahun!$A:$AM,27,FALSE),"") -> 1.1044846 | AB5: =IFERROR(VLOOKUP($A5,koronahun!$A:$AM,28,FALSE),"") -> 0 | AC5: =IFERROR(VLOOKUP($A5,koronahun!$A:$AM,29,FALSE),"") -> 672 | AD5: =IFERROR(VLOOKUP($A5,koronahun!$A:$AM,30,FALSE),"") -> 7.1428571 | AE5: =IFERROR(VLOOKUP($A5,koronahun!$A:$AM,31,FALSE),"") -> 0 | AF5: =IFERROR(VLOOKUP($A5,koronahun!$A:$AM,32,FALSE),"") -> 0 | AG5: =IFERROR(VLOOKUP($A5,koronahun!$A:$AM,33,FALSE),"") -> 6420354 | AH5: =IFERROR(VLOOKUP($A5,koronahun!$A:$AM,34,FALSE),"") -> 152 | AI5: =IFERROR(VLOOKUP($A5,koronahun!$A:$AM,35,FALSE),"") -> 21.714286 | AJ5: =IFERROR(VLOOKUP($A5,koronahun!$A:$AM,36,FALSE),"") -> 6206710 | AK5: =IFERROR(VLOOKUP($A5,koronahun!$A:$AM,37,FALSE),"") -> 145 | AL5: =IFERROR(VLOOKUP($A5,koronahun!$A:$AM,38,FALSE),"") -> 20.714286 | AM5: =IFERROR(VLOOKUP($A5,koronahun!$A:$AM,39,FALSE),"") -> 753.85714 | AN5: =IFERROR(__xludf.DUMMYFUNCTION("""COMPUTED_VALUE"""),43897) -> 43897 | AO5: =IFERROR(VLOOKUP(AN5,koronahun!A:B,2,FALSE),"") -> 5 | AP5: =IF(AO5="","",AN5) -> 43897 | AQ5: =IFERROR(__xludf.DUMMYFUNCTION("""COMPUTED_VALUE"""),43897) -> 43897 | AR5: 44909 | AS5: =IF(AR5="",AR6,AR5) -> 44909 | AT5: =IFERROR(__xludf.DUMMYFUNCTION("""COMPUTED_VALUE"""),44902) -> 44902
A6: 44895 | B6: =IFERROR(VLOOKUP($A6,koronahun!$A:$AM,2,FALSE),"") -> 2166352 | C6: =IFERROR(VLOOKUP($A6,koronahun!$A:$AM,3,FALSE),"") -> 4259 | D6: =IFERROR(VLOOKUP($A6,koronahun!$A:$AM,4,FALSE),"") -> 48287 | E6: =IFERROR(VLOOKUP($A6,koronahun!$A:$AM,5,FALSE),"") -> 2104358 | F6: =IFERROR(VLOOKUP($A6,koronahun!$A:$AM,6,FALSE),"") -> 11394556 | G6: =IFERROR(VLOOKUP($A6,koronahun!$A:$AM,7,FALSE),"") -> 1162709.8 | H6: =IFERROR(VLOOKUP($A6,koronahun!$A:$AM,8,FALSE),"") -> 0 | I6: =IFERROR(VLOOKUP($A6,koronahun!$A:$AM,9,FALSE),"") -> 0.0019698505 | J6: =IFERROR(VLOOKUP($A6,koronahun!$A:$AM,10,FALSE),"") -> 0.19012167 | K6: =IFERROR(VLOOKUP($A6,koronahun!$A:$AM,11,FALSE),"") -> 0 | L6: =IFERROR(VLOOKUP($A6,koronahun!$A:$AM,12,FALSE),"") -> 13707 | M6: =IFERROR(VLOOKUP($A6,koronahun!$A:$AM,13,FALSE),"") -> 0.022289545 | N6: =IFERROR(VLOOKUP($A6,koronahun!$A:$AM,14,FALSE),"") -> 0.97138323 | O6: =IFERROR(VLOOKUP($A6,koronahun!$A:$AM,15,FALSE),"") -> 0 | P6: =IFERROR(VLOOKUP($A6,koronahun!$A:$AM,16,FALSE),"") -> 0 | Q6: =IFERROR(VLOOKUP($A6,koronahun!$A:$AM,17,FALSE),"") -> 0 | R6: =IFERROR(VLOOKUP($A6,koronahun!$A:$AM,18,FALSE),"") -> 42 | S6: =IFERROR(VLOOKUP($A6,koronahun!$A:$AM,19,FALSE),"") -> 6118 | T6: =IFERROR(VLOOKUP($A6,koronahun!$A:$AM,20,FALSE),"") -> 336 | U6: =IFERROR(VLOOKUP($A6,koronahun!$A:$AM,21,FALSE),"") -> 7 | V6: =IFERROR(VLOOKUP($A6,koronahun!$A:$AM,22,FALSE),"") -> 0.0063272266 | W6: =IFERROR(VLOOKUP($A6,koronahun!$A:$AM,23,FALSE),"") -> 1345 | X6: =IFERROR(VLOOKUP($A6,koronahun!$A:$AM,24,FALSE),"") -> 19 | Y6: =IFERROR(VLOOKUP($A6,koronahun!$A:$AM,25,FALSE),"") -> 0.024513023 | Z6: =IFERROR(VLOOKUP($A6,koronahun!$A:$AM,26,FALSE),"") -> 0.020833333 | AA6: =IFERROR(VLOOKUP($A6,koronahun!$A:$AM,27,FALSE),"") -> 1.0392875 | AB6: =IFERROR(VLOOKUP($A6,koronahun!$A:$AM,28,FALSE),"") -> 0 | AC6: =IFERROR(VLOOKUP($A6,koronahun!$A:$AM,29,FALSE),"") -> 608.42857 | AD6: =IFERROR(VLOOKUP($A6,koronahun!$A:$AM,30,FALSE),"") -> 6 | AE6: =IFERROR(VLOOKUP($A6,koronahun!$A:$AM,31,FALSE),"") -> 0 | AF6: =IFERROR(VLOOKUP($A6,koronahun!$A:$AM,32,FALSE),"") -> 0 | AG6: =IFERROR(VLOOKUP($A6,koronahun!$A:$AM,33,FALSE),"") -> 6420202 | AH6: =IFERROR(VLOOKUP($A6,koronahun!$A:$AM,34,FALSE),"") -> 206 | AI6: =IFERROR(VLOOKUP($A6,koronahun!$A:$AM,35,FALSE),"") -> 29.428571 | AJ6: =IFERROR(VLOOKUP($A6,koronahun!$A:$AM,36,FALSE),"") -> 6206565 | AK6: =IFERROR(VLOOKUP($A6,koronahun!$A:$AM,37,FALSE),"") -> 177 | AL6: =IFERROR(VLOOKUP($A6,koronahun!$A:$AM,38,FALSE),"") -> 25.285714 | AM6: =IFERROR(VLOOKUP($A6,koronahun!$A:$AM,39,FALSE),"") -> 874 | AN6: =IFERROR(__xludf.DUMMYFUNCTION("""COMPUTED_VALUE"""),43898) -> 43898 | AO6: =IFERROR(VLOOKUP(AN6,koronahun!A:B,2,FALSE),"") -> 7 | AP6: =IF(AO6="","",AN6) -> 43898 | AQ6: =IFERROR(__xludf.DUMMYFUNCTION("""COMPUTED_VALUE"""),43898) -> 43898 | AR6: 44902 | AS6: =IF(AR6="",AR7,AR6) -> 44902 | AT6: =IFERROR(__xludf.DUMMYFUNCTION("""COMPUTED_VALUE"""),44895) -> 44895
A7: 44888 | B7: =IFERROR(VLOOKUP($A7,koronahun!$A:$AM,2,FALSE),"") -> 2162093 | C7: =IFERROR(VLOOKUP($A7,koronahun!$A:$AM,3,FALSE),"") -> 4098 | D7: =IFERROR(VLOOKUP($A7,koronahun!$A:$AM,4,FALSE),"") -> 48245 | E7: =IFERROR(VLOOKUP($A7,koronahun!$A:$AM,5,FALSE),"") -> 2098240 | F7: =IFERROR(VLOOKUP($A7,koronahun!$A:$AM,6,FALSE),"") -> 11394556 | G7: =IFERROR(VLOOKUP($A7,koronahun!$A:$AM,7,FALSE),"") -> 1162709.8 | H7: =IFERROR(VLOOKUP($A7,koronahun!$A:$AM,8,FALSE),"") -> 0 | I7: =IFERROR(VLOOKUP($A7,koronahun!$A:$AM,9,FALSE),"") -> 0.0018989849 | J7: =IFERROR(VLOOKUP($A7,koronahun!$A:$AM,10,FALSE),"") -> 0.18974789 | K7: =IFERROR(VLOOKUP($A7,koronahun!$A:$AM,11,FALSE),"") -> 0 | L7: =IFERROR(VLOOKUP($A7,koronahun!$A:$AM,12,FALSE),"") -> 15608 | M7: =IFERROR(VLOOKUP($A7,koronahun!$A:$AM,13,FALSE),"") -> 0.022314026 | N7: =IFERROR(VLOOKUP($A7,koronahun!$A:$AM,14,FALSE),"") -> 0.97046704 | O7: =IFERROR(VLOOKUP($A7,koronahun!$A:$AM,15,FALSE),"") -> 0 | P7: =IFERROR(VLOOKUP($A7,koronahun!$A:$AM,16,FALSE),"") -> 0 | Q7: =IFERROR(VLOOKUP($A7,koronahun!$A:$AM,17,FALSE),"") -> 0 | R7: =IFERROR(VLOOKUP($A7,koronahun!$A:$AM,18,FALSE),"") -> 61 | S7: =IFERROR(VLOOKUP($A7,koronahun!$A:$AM,19,FALSE),"") -> 6962 | T7: =IFERROR(VLOOKUP($A7,koronahun!$A:$AM,20,FALSE),"") -> 770 | U7: =IFERROR(VLOOKUP($A7,koronahun!$A:$AM,21,FALSE),"") -> 11 | V7: =IFERROR(VLOOKUP($A7,koronahun!$A:$AM,22,FALSE),"") -> 0.0072189309 | W7: =IFERROR(VLOOKUP($A7,koronahun!$A:$AM,23,FALSE),"") -> 1345 | X7: =IFERROR(VLOOKUP($A7,koronahun!$A:$AM,24,FALSE),"") -> 19 | Y7: =IFERROR(VLOOKUP($A7,koronahun!$A:$AM,25,FALSE),"") -> 0.049333675 | Z7: =IFERROR(VLOOKUP($A7,koronahun!$A:$AM,26,FALSE),"") -> 0.014285714 | AA7: =IFERROR(VLOOKUP($A7,koronahun!$A:$AM,27,FALSE),"") -> 0.92484766 | AB7: =IFERROR(VLOOKUP($A7,koronahun!$A:$AM,28,FALSE),"") -> 0 | AC7: =IFERROR(VLOOKUP($A7,koronahun!$A:$AM,29,FALSE),"") -> 585.42857 | AD7: =IFERROR(VLOOKUP($A7,koronahun!$A:$AM,30,FALSE),"") -> 8.7142857 | AE7: =IFERROR(VLOOKUP($A7,koronahun!$A:$AM,31,FALSE),"") -> 0 | AF7: =IFERROR(VLOOKUP($A7,koronahun!$A:$AM,32,FALSE),"") -> 0 | AG7: =IFERROR(VLOOKUP($A7,koronahun!$A:$AM,33,FALSE),"") -> 6419996 | AH7: =IFERROR(VLOOKUP($A7,koronahun!$A:$AM,34,FALSE),"") -> 238 | AI7: =IFERROR(VLOOKUP($A7,koronahun!$A:$AM,35,FALSE),"") -> 34 | AJ7: =IFERROR(VLOOKUP($A7,koronahun!$A:$AM,36,FALSE),"") -> 6206388 | AK7: =IFERROR(VLOOKUP($A7,koronahun!$A:$AM,37,FALSE),"") -> 232 | AL7: =IFERROR(VLOOKUP($A7,koronahun!$A:$AM,38,FALSE),"") -> 33.142857 | AM7: =IFERROR(VLOOKUP($A7,koronahun!$A:$AM,39,FALSE),"") -> 994.57143 | AN7: =IFERROR(__xludf.DUMMYFUNCTION("""COMPUTED_VALUE"""),43899) -> 43899 | AO7: =IFERROR(VLOOKUP(AN7,koronahun!A:B,2,FALSE),"") -> 9 | AP7: =IF(AO7="","",AN7) -> 43899 | AQ7: =IFERROR(__xludf.DUMMYFUNCTION("""COMPUTED_VALUE"""),43899) -> 43899 | AR7: 44895 | AS7: =IF(AR7="",AR8,AR7) -> 44895 | AT7: =IFERROR(__xludf.DUMMYFUNCTION("""COMPUTED_VALUE"""),44888) -> 44888
A8: 44881 | B8: =IFERROR(VLOOKUP($A8,koronahun!$A:$AM,2,FALSE),"") -> 2157995 | C8: =IFERROR(VLOOKUP($A8,koronahun!$A:$AM,3,FALSE),"") -> 4431 | D8: =IFERROR(VLOOKUP($A8,koronahun!$A:$AM,4,FALSE),"") -> 48184 | E8: =IFERROR(VLOOKUP($A8,koronahun!$A:$AM,5,FALSE),"") -> 2091278 | F8: =IFERROR(VLOOKUP($A8,koronahun!$A:$AM,6,FALSE),"") -> 11394556 | G8: =IFERROR(VLOOKUP($A8,koronahun!$A:$AM,7,FALSE),"") -> 1162709.8 | H8: =IFERROR(VLOOKUP($A8,koronahun!$A:$AM,8,FALSE),"") -> 0 | I8: =IFERROR(VLOOKUP($A8,koronahun!$A:$AM,9,FALSE),"") -> 0.0020575195 | J8: =IFERROR(VLOOKUP($A8,koronahun!$A:$AM,10,FALSE),"") -> 0.18938825 | K8: =IFERROR(VLOOKUP($A8,koronahun!$A:$AM,11,FALSE),"") -> 0 | L8: =IFERROR(VLOOKUP($A8,koronahun!$A:$AM,12,FALSE),"") -> 18533 | M8: =IFERROR(VLOOKUP($A8,koronahun!$A:$AM,13,FALSE),"") -> 0.022328133 | N8: =IFERROR(VLOOKUP($A8,koronahun!$A:$AM,14,FALSE),"") -> 0.9690838 | O8: =IFERROR(VLOOKUP($A8,koronahun!$A:$AM,15,FALSE),"") -> 0 | P8: =IFERROR(VLOOKUP($A8,koronahun!$A:$AM,16,FALSE),"") -> 0 | Q8: =IFERROR(VLOOKUP($A8,koronahun!$A:$AM,17,FALSE),"") -> 0 | R8: =IFERROR(VLOOKUP($A8,koronahun!$A:$AM,18,FALSE),"") -> 73 | S8: =IFERROR(VLOOKUP($A8,koronahun!$A:$AM,19,FALSE),"") -> 8753 | T8: =IFERROR(VLOOKUP($A8,koronahun!$A:$AM,20,FALSE),"") -> 749 | U8: =IFERROR(VLOOKUP($A8,koronahun!$A:$AM,21,FALSE),"") -> 10 | V8: =IFERROR(VLOOKUP($A8,koronahun!$A:$AM,22,FALSE),"") -> 0.0085880644 | W8: =IFERROR(VLOOKUP($A8,koronahun!$A:$AM,23,FALSE),"") -> 1345 | X8: =IFERROR(VLOOKUP($A8,koronahun!$A:$AM,24,FALSE),"") -> 19 | Y8: =IFERROR(VLOOKUP($A8,koronahun!$A:$AM,25,FALSE),"") -> 0.040414396 | Z8: =IFERROR(VLOOKUP($A8,koronahun!$A:$AM,26,FALSE),"") -> 0.013351135 | AA8: =IFERROR(VLOOKUP($A8,koronahun!$A:$AM,27,FALSE),"") -> 0.97256365 | AB8: =IFERROR(VLOOKUP($A8,koronahun!$A:$AM,28,FALSE),"") -> 0 | AC8: =IFERROR(VLOOKUP($A8,koronahun!$A:$AM,29,FALSE),"") -> 633 | AD8: =IFERROR(VLOOKUP($A8,koronahun!$A:$AM,30,FALSE),"") -> 10.428571 | AE8: =IFERROR(VLOOKUP($A8,koronahun!$A:$AM,31,FALSE),"") -> 0 | AF8: =IFERROR(VLOOKUP($A8,koronahun!$A:$AM,32,FALSE),"") -> 0 | AG8: =IFERROR(VLOOKUP($A8,koronahun!$A:$AM,33,FALSE),"") -> 6419758 | AH8: =IFERROR(VLOOKUP($A8,koronahun!$A:$AM,34,FALSE),"") -> 191 | AI8: =IFERROR(VLOOKUP($A8,koronahun!$A:$AM,35,FALSE),"") -> 27.285714 | AJ8: =IFERROR(VLOOKUP($A8,koronahun!$A:$AM,36,FALSE),"") -> 6206156 | AK8: =IFERROR(VLOOKUP($A8,koronahun!$A:$AM,37,FALSE),"") -> 188 | AL8: =IFERROR(VLOOKUP($A8,koronahun!$A:$AM,38,FALSE),"") -> 26.857143 | AM8: =IFERROR(VLOOKUP($A8,koronahun!$A:$AM,39,FALSE),"") -> 1250.4286 | AN8: =IFERROR(__xludf.DUMMYFUNCTION("""COMPUTED_VALUE"""),43900) -> 43900 | AO8: =IFERROR(VLOOKUP(AN8,koronahun!A:B,2,FALSE),"") -> 12 | AP8: =IF(AO8="","",AN8) -> 43900 | AQ8: =IFERROR(__xludf.DUMMYFUNCTION("""COMPUTED_VALUE"""),43900) -> 43900 | AR8: 44888 | AS8: =IF(AR8="",AR9,AR8) -> 44888 | AT8: =IFERROR(__xludf.DUMMYFUNCTION("""COMPUTED_VALUE"""),44881) -> 44881
A9: 44874 | B9: =IFERROR(VLOOKUP($A9,koronahun!$A:$AM,2,FALSE),"") -> 2153564 | C9: =IFERROR(VLOOKUP($A9,koronahun!$A:$AM,3,FALSE),"") -> 4556 | D9: =IFERROR(VLOOKUP($A9,koronahun!$A:$AM,4,FALSE),"") -> 48111 | E9: =IFERROR(VLOOKUP($A9,koronahun!$A:$AM,5,FALSE),"") -> 2082525 | F9: =IFERROR(VLOOKUP($A9,koronahun!$A:$AM,6,FALSE),"") -> 11394556 | G9: =IFERROR(VLOOKUP($A9,koronahun!$A:$AM,7,FALSE),"") -> 1162709.8 | H9: =IFERROR(VLOOKUP($A9,koronahun!$A:$AM,8,FALSE),"") -> 0 | I9: =IFERROR(VLOOKUP($A9,koronahun!$A:$AM,9,FALSE),"") -> 0.0021200479 | J9: =IFERROR(VLOOKUP($A9,koronahun!$A:$AM,10,FALSE),"") -> 0.18899938 | K9: =IFERROR(VLOOKUP($A9,koronahun!$A:$AM,11,FALSE),"") -> 0 | L9: =IFERROR(VLOOKUP($A9,koronahun!$A:$AM,12,FALSE),"") -> 22928 | M9: =IFERROR(VLOOKUP($A9,koronahun!$A:$AM,13,FALSE),"") -> 0.022340177 | N9: =IFERROR(VLOOKUP($A9,koronahun!$A:$AM,14,FALSE),"") -> 0.96701329 | O9: =IFERROR(VLOOKUP($A9,koronahun!$A:$AM,15,FALSE),"") -> 0 | P9: =IFERROR(VLOOKUP($A9,koronahun!$A:$AM,16,FALSE),"") -> 0 | Q9: =IFERROR(VLOOKUP($A9,koronahun!$A:$AM,17,FALSE),"") -> 0 | R9: =IFERROR(VLOOKUP($A9,koronahun!$A:$AM,18,FALSE),"") -> 173 | S9: =IFERROR(VLOOKUP($A9,koronahun!$A:$AM,19,FALSE),"") -> 20526 | T9: =IFERROR(VLOOKUP($A9,koronahun!$A:$AM,20,FALSE),"") -> 985 | U9: =IFERROR(VLOOKUP($A9,koronahun!$A:$AM,21,FALSE),"") -> 18 | V9: =IFERROR(VLOOKUP($A9,koronahun!$A:$AM,22,FALSE),"") -> 0.010646538 | W9: =IFERROR(VLOOKUP($A9,koronahun!$A:$AM,23,FALSE),"") -> 1345 | X9: =IFERROR(VLOOKUP($A9,koronahun!$A:$AM,24,FALSE),"") -> 19 | Y9: =IFERROR(VLOOKUP($A9,koronahun!$A:$AM,25,FALSE),"") -> 0.042960572 | Z9: =IFERROR(VLOOKUP($A9,koronahun!$A:$AM,26,FALSE),"") -> 0.018274112 | AA9: =IFERROR(VLOOKUP($A9,koronahun!$A:$AM,27,FALSE),"") -> 0.60787191 | AB9: =IFERROR(VLOOKUP($A9,koronahun!$A:$AM,28,FALSE),"") -> 0 | AC9: =IFERROR(VLOOKUP($A9,koronahun!$A:$AM,29,FALSE),"") -> 650.85714 | AD9: =IFERROR(VLOOKUP($A9,koronahun!$A:$AM,30,FALSE),"") -> 12.357143 | AE9: =IFERROR(VLOOKUP($A9,koronahun!$A:$AM,31,FALSE),"") -> 0 | AF9: =IFERROR(VLOOKUP($A9,koronahun!$A:$AM,32,FALSE),"") -> 0 | AG9: =IFERROR(VLOOKUP($A9,koronahun!$A:$AM,33,FALSE),"") -> 6419567 | AH9: =IFERROR(VLOOKUP($A9,koronahun!$A:$AM,34,FALSE),"") -> 384 | AI9: =IFERROR(VLOOKUP($A9,koronahun!$A:$AM,35,FALSE),"") -> 54.857143 | AJ9: =IFERROR(VLOOKUP($A9,koronahun!$A:$AM,36,FALSE),"") -> 6205968 | AK9: =IFERROR(VLOOKUP($A9,koronahun!$A:$AM,37,FALSE),"") -> 360 | AL9: =IFERROR(VLOOKUP($A9,koronahun!$A:$AM,38,FALSE),"") -> 51.428571 | AM9: =IFERROR(VLOOKUP($A9,koronahun!$A:$AM,39,FALSE),"") -> 1466.1429 | AN9: =IFERROR(__xludf.DUMMYFUNCTION("""COMPUTED_VALUE"""),43901) -> 43901 | AO9: =IFERROR(VLOOKUP(AN9,koronahun!A:B,2,FALSE),"") -> 13 | AP9: =IF(AO9="","",AN9) -> 43901 | AQ9: =IFERROR(__xludf.DUMMYFUNCTION("""COMPUTED_VALUE"""),43901) -> 43901 | AR9: 44881 | AS9: =IF(AR9="",AR10,AR9) -> 44881 | AT9: =IFERROR(__xludf.DUMMYFUNCTION("""COMPUTED_VALUE"""),44874) -> 44874
A10: 44867 | B10: =IFERROR(VLOOKUP($A10,koronahun!$A:$AM,2,FALSE),"") -> 2149008 | C10: =IFERROR(VLOOKUP($A10,koronahun!$A:$AM,3,FALSE),"") -> 7495 | D10: =IFERROR(VLOOKUP($A10,koronahun!$A:$AM,4,FALSE),"") -> 0 | E10: =IFERROR(VLOOKUP($A10,koronahun!$A:$AM,5,FALSE),"") -> 0 | F10: =IFERROR(VLOOKUP($A10,koronahun!$A:$AM,6,FALSE),"") -> 11394556 | G10: =IFERROR(VLOOKUP($A10,koronahun!$A:$AM,7,FALSE),"") -> 1162709.8 | H10: =IFERROR(VLOOKUP($A10,koronahun!$A:$AM,8,FALSE),"") -> 0 | I10: =IFERROR(VLOOKUP($A10,koronahun!$A:$AM,9,FALSE),"") -> 0.003499862 | J10: =IFERROR(VLOOKUP($A10,koronahun!$A:$AM,10,FALSE),"") -> 0.18859954 | K10: =IFERROR(VLOOKUP($A10,koronahun!$A:$AM,11,FALSE),"") -> 0 | L10: =IFERROR(VLOOKUP($A10,koronahun!$A:$AM,12,FALSE),"") -> 0 | M10: =IFERROR(VLOOKUP($A10,koronahun!$A:$AM,13,FALSE),"") -> 0 | N10: =IFERROR(VLOOKUP($A10,koronahun!$A:$AM,14,FALSE),"") -> 0 | O10: =IFERROR(VLOOKUP($A10,koronahun!$A:$AM,15,FALSE),"") -> 0 | P10: =IFERROR(VLOOKUP($A10,koronahun!$A:$AM,16,FALSE),"") -> 0 | Q10: =IFERROR(VLOOKUP($A10,koronahun!$A:$AM,17,FALSE),"") -> 0 | R10: =IFERROR(VLOOKUP($A10,koronahun!$A:$AM,18,FALSE),"") -> 0 | S10: =IFERROR(VLOOKUP($A10,koronahun!$A:$AM,19,FALSE),"") -> 0 | T10: =IFERROR(VLOOKUP($A10,koronahun!$A:$AM,20,FALSE),"") -> 0 | U10: =IFERROR(VLOOKUP($A10,koronahun!$A:$AM,21,FALSE),"") -> 0 | V10: =IFERROR(VLOOKUP($A10,koronahun!$A:$AM,22,FALSE),"") -> 0 | W10: =IFERROR(VLOOKUP($A10,koronahun!$A:$AM,23,FALSE),"") -> 0 | X10: =IFERROR(VLOOKUP($A10,koronahun!$A:$AM,24,FALSE),"") -> 0 | Y10: =IFERROR(VLOOKUP($A10,koronahun!$A:$AM,25,FALSE),"") -> 0 | Z10: =IFERROR(VLOOKUP($A10,koronahun!$A:$AM,26,FALSE),"") -> 0 | AA10: =IFERROR(VLOOKUP($A10,koronahun!$A:$AM,27,FALSE),"") -> 0.83065499 | AB10: =IFERROR(VLOOKUP($A10,koronahun!$A:$AM,28,FALSE),"") -> 0 | AC10: =IFERROR(VLOOKUP($A10,koronahun!$A:$AM,29,FALSE),"") -> 1070.7143 | AD10: =IFERROR(VLOOKUP($A10,koronahun!$A:$AM,30,FALSE),"") -> 0 | AE10: =IFERROR(VLOOKUP($A10,koronahun!$A:$AM,31,FALSE),"") -> 0 | AF10: =IFERROR(VLOOKUP($A10,koronahun!$A:$AM,32,FALSE),"") -> 0 | AG10: =IFERROR(VLOOKUP($A10,koronahun!$A:$AM,33,FALSE),"") -> 0 | AH10: =IFERROR(VLOOKUP($A10,koronahun!$A:$AM,34,FALSE),"") -> 0 | AI10: =IFERROR(VLOOKUP($A10,koronahun!$A:$AM,35,FALSE),"") -> 0 | AJ10: =IFERROR(VLOOKUP($A10,koronahun!$A:$AM,36,FALSE),"") -> 0 | AK10: =IFERROR(VLOOKUP($A10,koronahun!$A:$AM,37,FALSE),"") -> 0 | AL10: =IFERROR(VLOOKUP($A10,koronahun!$A:$AM,38,FALSE),"") -> 0 | AM10: =IFERROR(VLOOKUP($A10,koronahun!$A:$AM,39,FALSE),"") -> 0 | AN10: =IFERROR(__xludf.DUMMYFUNCTION("""COMPUTED_VALUE"""),43902) -> 43902 | AO10: =IFERROR(VLOOKUP(AN10,koronahun!A:B,2,FALSE),"") -> 16 | AP10: =IF(AO10="","",AN10) -> 43902 | AQ10: =IFERROR(__xludf.DUMMYFUNCTION("""COMPUTED_VALUE"""),43902) -> 43902 | AR10: 44874 | AS10: =IF(AR10="",AR11,AR10) -> 44874 | AT10: =IFERROR(__xludf.DUMMYFUNCTION("""COMPUTED_VALUE"""),44867) -> 44867
A11: 44860 | B11: =IFERROR(VLOOKUP($A11,koronahun!$A:$AM,2,FALSE),"") -> 2141513 | C11: =IFERROR(VLOOKUP($A11,koronahun!$A:$AM,3,FALSE),"") -> 9023 | D11: =IFERROR(VLOOKUP($A11,koronahun!$A:$AM,4,FALSE),"") -> 47938 | E11: =IFERROR(VLOOKUP($A11,koronahun!$A:$AM,5,FALSE),"") -> 2061999 | F11: =IFERROR(VLOOKUP($A11,koronahun!$A:$AM,6,FALSE),"") -> 11394556 | G11: =IFERROR(VLOOKUP($A11,koronahun!$A:$AM,7,FALSE),"") -> 1162709.8 | H11: =IFERROR(VLOOKUP($A11,koronahun!$A:$AM,8,FALSE),"") -> 0 | I11: =IFERROR(VLOOKUP($A11,koronahun!$A:$AM,9,FALSE),"") -> 0.0042312039 | J11: =IFERROR(VLOOKUP($A11,koronahun!$A:$AM,10,FALSE),"") -> 0.18794177 | K11: =IFERROR(VLOOKUP($A11,koronahun!$A:$AM,11,FALSE),"") -> 0 | L11: =IFERROR(VLOOKUP($A11,koronahun!$A:$AM,12,FALSE),"") -> 31576 | M11: =IFERROR(VLOOKUP($A11,koronahun!$A:$AM,13,FALSE),"") -> 0.022385108 | N11: =IFERROR(VLOOKUP($A11,koronahun!$A:$AM,14,FALSE),"") -> 0.96287018 | O11: =IFERROR(VLOOKUP($A11,koronahun!$A:$AM,15,FALSE),"") -> 0 | P11: =IFERROR(VLOOKUP($A11,koronahun!$A:$AM,16,FALSE),"") -> 0 | Q11: =IFERROR(VLOOKUP($A11,koronahun!$A:$AM,17,FALSE),"") -> 0 | R11: =IFERROR(VLOOKUP($A11,koronahun!$A:$AM,18,FALSE),"") -> 140 | S11: =IFERROR(VLOOKUP($A11,koronahun!$A:$AM,19,FALSE),"") -> 12350 | T11: =IFERROR(VLOOKUP($A11,koronahun!$A:$AM,20,FALSE),"") -> 1371 | U11: =IFERROR(VLOOKUP($A11,koronahun!$A:$AM,21,FALSE),"") -> 25 | V11: =IFERROR(VLOOKUP($A11,koronahun!$A:$AM,22,FALSE),"") -> 0.014744716 | W11: =IFERROR(VLOOKUP($A11,koronahun!$A:$AM,23,FALSE),"") -> 1345 | X11: =IFERROR(VLOOKUP($A11,koronahun!$A:$AM,24,FALSE),"") -> 19 | Y11: =IFERROR(VLOOKUP($A11,koronahun!$A:$AM,25,FALSE),"") -> 0.043419052 | Z11: =IFERROR(VLOOKUP($A11,koronahun!$A:$AM,26,FALSE),"") -> 0.018234865 | AA11: =IFERROR(VLOOKUP($A11,koronahun!$A:$AM,27,FALSE),"") -> 0.75525236 | AB11: =IFERROR(VLOOKUP($A11,koronahun!$A:$AM,28,FALSE),"") -> 0 | AC11: =IFERROR(VLOOKUP($A11,koronahun!$A:$AM,29,FALSE),"") -> 1289 | AD11: =IFERROR(VLOOKUP($A11,koronahun!$A:$AM,30,FALSE),"") -> 20 | AE11: =IFERROR(VLOOKUP($A11,koronahun!$A:$AM,31,FALSE),"") -> 0 | AF11: =IFERROR(VLOOKUP($A11,koronahun!$A:$AM,32,FALSE),"") -> 0 | AG11: =IFERROR(VLOOKUP($A11,koronahun!$A:$AM,33,FALSE),"") -> 6419183 | AH11: =IFERROR(VLOOKUP($A11,koronahun!$A:$AM,34,FALSE),"") -> 373 | AI11: =IFERROR(VLOOKUP($A11,koronahun!$A:$AM,35,FALSE),"") -> 53.285714 | AJ11: =IFERROR(VLOOKUP($A11,koronahun!$A:$AM,36,FALSE),"") -> 6205608 | AK11: =IFERROR(VLOOKUP($A11,koronahun!$A:$AM,37,FALSE),"") -> 281 | AL11: =IFERROR(VLOOKUP($A11,koronahun!$A:$AM,38,FALSE),"") -> 40.142857 | AM11: =IFERROR(VLOOKUP($A11,koronahun!$A:$AM,39,FALSE),"") -> 1764.2857 | AN11: =IFERROR(__xludf.DUMMYFUNCTION("""COMPUTED_VALUE"""),43903) -> 43903 | AO11: =IFERROR(VLOOKUP(AN11,koronahun!A:B,2,FALSE),"") -> 19 | AP11: =IF(AO11="","",AN11) -> 43903 | AQ11: =IFERROR(__xludf.DUMMYFUNCTION("""COMPUTED_VALUE"""),43903) -> 43903 | AR11: 44867 | AS11: =IF(AR11="",AR12,AR11) -> 44867 | AT11: =IFERROR(__xludf.DUMMYFUNCTION("""COMPUTED_VALUE"""),44860) -> 44860
A12: 44853 | B12: =IFERROR(VLOOKUP($A12,koronahun!$A:$AM,2,FALSE),"") -> 2132490 | C12: =IFERROR(VLOOKUP($A12,koronahun!$A:$AM,3,FALSE),"") -> 11947 | D12: =IFERROR(VLOOKUP($A12,koronahun!$A:$AM,4,FALSE),"") -> 47798 | E12: =IFERROR(VLOOKUP($A12,koronahun!$A:$AM,5,FALSE),"") -> 2049649 | F12: =IFERROR(VLOOKUP($A12,koronahun!$A:$AM,6,FALSE),"") -> 11394556 | G12: =IFERROR(VLOOKUP($A12,koronahun!$A:$AM,7,FALSE),"") -> 1162709.8 | H12: =IFERROR(VLOOKUP($A12,koronahun!$A:$AM,8,FALSE),"") -> 0 | I12: =IFERROR(VLOOKUP($A12,koronahun!$A:$AM,9,FALSE),"") -> 0.0056339343 | J12: =IFERROR(VLOOKUP($A12,koronahun!$A:$AM,10,FALSE),"") -> 0.1871499 | K12: =IFERROR(VLOOKUP($A12,koronahun!$A:$AM,11,FALSE),"") -> 0 | L12: =IFERROR(VLOOKUP($A12,koronahun!$A:$AM,12,FALSE),"") -> 35043 | M12: =IFERROR(VLOOKUP($A12,koronahun!$A:$AM,13,FALSE),"") -> 0.022414173 | N12: =IFERROR(VLOOKUP($A12,koronahun!$A:$AM,14,FALSE),"") -> 0.96115292 | O12: =IFERROR(VLOOKUP($A12,koronahun!$A:$AM,15,FALSE),"") -> 0 | P12: =IFERROR(VLOOKUP($A12,koronahun!$A:$AM,16,FALSE),"") -> 0 | Q12: =IFERROR(VLOOKUP($A12,koronahun!$A:$AM,17,FALSE),"") -> 0 | R12: =IFERROR(VLOOKUP($A12,koronahun!$A:$AM,18,FALSE),"") -> 118 | S12: =IFERROR(VLOOKUP($A12,koronahun!$A:$AM,19,FALSE),"") -> 12949 | T12: =IFERROR(VLOOKUP($A12,koronahun!$A:$AM,20,FALSE),"") -> 1597 | U12: =IFERROR(VLOOKUP($A12,koronahun!$A:$AM,21,FALSE),"") -> 18 | V12: =IFERROR(VLOOKUP($A12,koronahun!$A:$AM,22,FALSE),"") -> 0.016432902 | W12: =IFERROR(VLOOKUP($A12,koronahun!$A:$AM,23,FALSE),"") -> 1345 | X12: =IFERROR(VLOOKUP($A12,koronahun!$A:$AM,24,FALSE),"") -> 19 | Y12: =IFERROR(VLOOKUP($A12,koronahun!$A:$AM,25,FALSE),"") -> 0.045572582 | Z12: =IFERROR(VLOOKUP($A12,koronahun!$A:$AM,26,FALSE),"") -> 0.011271133 | AA12: =IFERROR(VLOOKUP($A12,koronahun!$A:$AM,27,FALSE),"") -> 0.94547325 | AB12: =IFERROR(VLOOKUP($A12,koronahun!$A:$AM,28,FALSE),"") -> 0 | AC12: =IFERROR(VLOOKUP($A12,koronahun!$A:$AM,29,FALSE),"") -> 1706.7143 | AD12: =IFERROR(VLOOKUP($A12,koronahun!$A:$AM,30,FALSE),"") -> 16.857143 | AE12: =IFERROR(VLOOKUP($A12,koronahun!$A:$AM,31,FALSE),"") -> 0 | AF12: =IFERROR(VLOOKUP($A12,koronahun!$A:$AM,32,FALSE),"") -> 0 | AG12: =IFERROR(VLOOKUP($A12,koronahun!$A:$AM,33,FALSE),"") -> 6418810 | AH12: =IFERROR(VLOOKUP($A12,koronahun!$A:$AM,34,FALSE),"") -> 230 | AI12: =IFERROR(VLOOKUP($A12,koronahun!$A:$AM,35,FALSE),"") -> 32.857143 | AJ12: =IFERROR(VLOOKUP($A12,koronahun!$A:$AM,36,FALSE),"") -> 6205327 | AK12: =IFERROR(VLOOKUP($A12,koronahun!$A:$AM,37,FALSE),"") -> 260 | AL12: =IFERROR(VLOOKUP($A12,koronahun!$A:$AM,38,FALSE),"") -> 37.142857 | AM12: =IFERROR(VLOOKUP($A12,koronahun!$A:$AM,39,FALSE),"") -> 1849.8571 | AN12: =IFERROR(__xludf.DUMMYFUNCTION("""COMPUTED_VALUE"""),43904) -> 43904 | AO12: =IFERROR(VLOOKUP(AN12,koronahun!A:B,2,FALSE),"") -> 30 | AP12: =IF(AO12="","",AN12) -> 43904 | AQ12: =IFERROR(__xludf.DUMMYFUNCTION("""COMPUTED_VALUE"""),43904) -> 43904 | AR12: 44860 | AS12: =IF(AR12="",AR13,AR12) -> 44860 | AT12: =IFERROR(__xludf.DUMMYFUNCTION("""COMPUTED_VALUE"""),44853) -> 44853
A13: 44846 | B13: =IFERROR(VLOOKUP($A13,koronahun!$A:$AM,2,FALSE),"") -> 2120543 | C13: =IFERROR(VLOOKUP($A13,koronahun!$A:$AM,3,FALSE),"") -> 12636 | D13: =IFERROR(VLOOKUP($A13,koronahun!$A:$AM,4,FALSE),"") -> 47680 | E13: =IFERROR(VLOOKUP($A13,koronahun!$A:$AM,5,FALSE),"") -> 2036700 | F13: =IFERROR(VLOOKUP($A13,koronahun!$A:$AM,6,FALSE),"") -> 11394556 | G13: =IFERROR(VLOOKUP($A13,koronahun!$A:$AM,7,FALSE),"") -> 1162709.8 | H13: =IFERROR(VLOOKUP($A13,koronahun!$A:$AM,8,FALSE),"") -> 0 | I13: =IFERROR(VLOOKUP($A13,koronahun!$A:$AM,9,FALSE),"") -> 0.0059945719 | J13: =IFERROR(VLOOKUP($A13,koronahun!$A:$AM,10,FALSE),"") -> 0.18610142 | K13: =IFERROR(VLOOKUP($A13,koronahun!$A:$AM,11,FALSE),"") -> 0 | L13: =IFERROR(VLOOKUP($A13,koronahun!$A:$AM,12,FALSE),"") -> 36163 | M13: =IFERROR(VLOOKUP($A13,koronahun!$A:$AM,13,FALSE),"") -> 0.022484807 | N13: =IFERROR(VLOOKUP($A13,koronahun!$A:$AM,14,FALSE),"") -> 0.96046154 | O13: =IFERROR(VLOOKUP($A13,koronahun!$A:$AM,15,FALSE),"") -> 0 | P13: =IFERROR(VLOOKUP($A13,koronahun!$A:$AM,16,FALSE),"") -> 0 | Q13: =IFERROR(VLOOKUP($A13,koronahun!$A:$AM,17,FALSE),"") -> 0 | R13: =IFERROR(VLOOKUP($A13,koronahun!$A:$AM,18,FALSE),"") -> 104 | S13: =IFERROR(VLOOKUP($A13,koronahun!$A:$AM,19,FALSE),"") -> 11408 | T13: =IFERROR(VLOOKUP($A13,koronahun!$A:$AM,20,FALSE),"") -> 1700 | U13: =IFERROR(VLOOKUP($A13,koronahun!$A:$AM,21,FALSE),"") -> 32 | V13: =IFERROR(VLOOKUP($A13,koronahun!$A:$AM,22,FALSE),"") -> 0.017053651 | W13: =IFERROR(VLOOKUP($A13,koronahun!$A:$AM,23,FALSE),"") -> 1345 | X13: =IFERROR(VLOOKUP($A13,koronahun!$A:$AM,24,FALSE),"") -> 19 | Y13: =IFERROR(VLOOKUP($A13,koronahun!$A:$AM,25,FALSE),"") -> 0.047009374 | Z13: =IFERROR(VLOOKUP($A13,koronahun!$A:$AM,26,FALSE),"") -> 0.018823529 | AA13: =IFERROR(VLOOKUP($A13,koronahun!$A:$AM,27,FALSE),"") -> 0.91798039 | AB13: =IFERROR(VLOOKUP($A13,koronahun!$A:$AM,28,FALSE),"") -> 0 | AC13: =IFERROR(VLOOKUP($A13,koronahun!$A:$AM,29,FALSE),"") -> 1805.1429 | AD13: =IFERROR(VLOOKUP($A13,koronahun!$A:$AM,30,FALSE),"") -> 14.857143 | AE13: =IFERROR(VLOOKUP($A13,koronahun!$A:$AM,31,FALSE),"") -> 0 | AF13: =IFERROR(VLOOKUP($A13,koronahun!$A:$AM,32,FALSE),"") -> 0 | AG13: =IFERROR(VLOOKUP($A13,koronahun!$A:$AM,33,FALSE),"") -> 6418580 | AH13: =IFERROR(VLOOKUP($A13,koronahun!$A:$AM,34,FALSE),"") -> 228 | AI13: =IFERROR(VLOOKUP($A13,koronahun!$A:$AM,35,FALSE),"") -> 32.571429 | AJ13: =IFERROR(VLOOKUP($A13,koronahun!$A:$AM,36,FALSE),"") -> 6205067 | AK13: =IFERROR(VLOOKUP($A13,koronahun!$A:$AM,37,FALSE),"") -> 342 | AL13: =IFERROR(VLOOKUP($A13,koronahun!$A:$AM,38,FALSE),"") -> 48.857143 | AM13: =IFERROR(VLOOKUP($A13,koronahun!$A:$AM,39,FALSE),"") -> 1629.7143 | AN13: =IFERROR(__xludf.DUMMYFUNCTION("""COMPUTED_VALUE"""),43905) -> 43905 | AO13: =IFERROR(VLOOKUP(AN13,koronahun!A:B,2,FALSE),"") -> 32 | AP13: =IF(AO13="","",AN13) -> 43905 | AQ13: =IFERROR(__xludf.DUMMYFUNCTION("""COMPUTED_VALUE"""),43905) -> 43905 | AR13: 44853 | AS13: =IF(AR13="",AR14,AR13) -> 44853 | AT13: =IFERROR(__xludf.DUMMYFUNCTION("""COMPUTED_VALUE"""),44846) -> 44846
